<mujoco model="pendulum">

  <include file="../../common/visual.xml" />
  <include file="../../common/skybox.xml" />
  <include file="../../common/materials.xml" />

  <asset>
    <texture name="motphys_ground_tex" type="2d" file="../../common/motphys-ground.png" />
    <material name="motphys_ground_mat" texture="motphys_ground_tex" texrepeat="1 1" texuniform="true" />
  </asset>

  <option timestep="0.02">
    <flag contact="disable" energy="enable"/>
  </option>


  <worldbody>
    <light diffuse="0.6 0.6 0.6" pos="0 0 1.5"
      dir="-0.49835488200187683 0.2925136387348175 -0.8161361217498779" directional="true" />
    <geom name="floor" size="0 0 0.2" type="plane" material="motphys_ground_mat"/>
    <camera name="fixed" pos="0 -1.5 2" xyaxes='1 0 0 0 1 1'/>
    <camera name="lookat" mode="targetbodycom" target="pole" pos="0 -2 1"/>
    <body name="pole" pos="0 0 .6">
      <joint name="hinge" type="hinge" axis="0 1 0" damping="0.1"/>
      <geom name="base" material="decoration" type="cylinder" fromto="0 -.03 0 0 .03 0" size="0.021" mass="0"/>
      <geom name="pole" material="self" type="capsule" fromto="0 0 0 0 0 0.5" size="0.02" mass="0"/>
      <geom name="mass" material="effector" type="sphere" pos="0 0 0.5" size="0.05" mass="1"/>
    </body>
  </worldbody>

  <actuator>
    <motor name="torque" joint="hinge" gear="5" ctrlrange="-1 1" ctrllimited="true"/>
  </actuator>
</mujoco>

